Traceback (most recent call last):
  File "c:\anaconda3\lib\site-packages\jupyter_cache\executors\utils.py", line 56, in single_nb_execution
    record_timing=False,
  File "c:\anaconda3\lib\site-packages\nbclient\client.py", line 1082, in execute
    return NotebookClient(nb=nb, resources=resources, km=km, **kwargs).execute()
  File "c:\anaconda3\lib\site-packages\nbclient\util.py", line 74, in wrapped
    return just_run(coro(*args, **kwargs))
  File "c:\anaconda3\lib\site-packages\nbclient\util.py", line 53, in just_run
    return loop.run_until_complete(coro)
  File "c:\anaconda3\lib\asyncio\base_events.py", line 584, in run_until_complete
    return future.result()
  File "c:\anaconda3\lib\site-packages\nbclient\client.py", line 536, in async_execute
    cell, index, execution_count=self.code_cells_executed + 1
  File "c:\anaconda3\lib\site-packages\nbclient\client.py", line 827, in async_execute_cell
    self._check_raise_for_error(cell, exec_reply)
  File "c:\anaconda3\lib\site-packages\nbclient\client.py", line 735, in _check_raise_for_error
    raise CellExecutionError.from_cell_and_msg(cell, exec_reply['content'])
nbclient.exceptions.CellExecutionError: An error occurred while executing the following cell:
------------------
from laguide import Magnitude

U = np.array([[2],[3]])
print(Magnitude(A))
------------------

[1;31m---------------------------------------------------------------------------[0m
[1;31mNameError[0m                                 Traceback (most recent call last)
[1;32m<ipython-input-6-ef4e302124ba>[0m in [0;36m<module>[1;34m[0m
[0;32m      2[0m [1;33m[0m[0m
[0;32m      3[0m [0mU[0m [1;33m=[0m [0mnp[0m[1;33m.[0m[0marray[0m[1;33m([0m[1;33m[[0m[1;33m[[0m[1;36m2[0m[1;33m][0m[1;33m,[0m[1;33m[[0m[1;36m3[0m[1;33m][0m[1;33m][0m[1;33m)[0m[1;33m[0m[1;33m[0m[0m
[1;32m----> 4[1;33m [0mprint[0m[1;33m([0m[0mMagnitude[0m[1;33m([0m[0mA[0m[1;33m)[0m[1;33m)[0m[1;33m[0m[1;33m[0m[0m
[0m
[1;31mNameError[0m: name 'A' is not defined
NameError: name 'A' is not defined

