Traceback (most recent call last):
  File "c:\anaconda3\lib\site-packages\jupyter_cache\executors\utils.py", line 56, in single_nb_execution
    record_timing=False,
  File "c:\anaconda3\lib\site-packages\nbclient\client.py", line 1082, in execute
    return NotebookClient(nb=nb, resources=resources, km=km, **kwargs).execute()
  File "c:\anaconda3\lib\site-packages\nbclient\util.py", line 74, in wrapped
    return just_run(coro(*args, **kwargs))
  File "c:\anaconda3\lib\site-packages\nbclient\util.py", line 53, in just_run
    return loop.run_until_complete(coro)
  File "c:\anaconda3\lib\asyncio\base_events.py", line 584, in run_until_complete
    return future.result()
  File "c:\anaconda3\lib\site-packages\nbclient\client.py", line 536, in async_execute
    cell, index, execution_count=self.code_cells_executed + 1
  File "c:\anaconda3\lib\site-packages\nbclient\client.py", line 827, in async_execute_cell
    self._check_raise_for_error(cell, exec_reply)
  File "c:\anaconda3\lib\site-packages\nbclient\client.py", line 735, in _check_raise_for_error
    raise CellExecutionError.from_cell_and_msg(cell, exec_reply['content'])
nbclient.exceptions.CellExecutionError: An error occurred while executing the following cell:
------------------
## Directs the graphical output to this notebook
% matplotlib inline

## Imports the module and assigns a short alias for convenience
import matplotlib.pyplot as plt

## The subplots method returns a Figure object and an Axes object
fig, ax = plt.subplots()

## Plots the data on the Axes object
ax.plot(x,y);
------------------


UsageError: Line magic function `%` not found.

